[ 2023-08-03 12:11:49,845 ] 18 root - INFO - [data_validation.py] There is no problem with the data. So, we can continue further. The data passed 'validate()'
[ 2023-08-03 12:11:49,845 ] 19 root - INFO - Data Validation is completed successfully
